<?xml version="1.0" ?>
<robot name="left_arm" xmlns:xacro="http://playerstage.sourceforge.net/gazebo/xmlschema/#interface">

  <material name="blue">
    <color rgba="0 0 0.8 1"/>
  </material>
  <material name="black">
    <color rgba="0 0 0 1"/>
  </material>
  <material name="white">
    <color rgba="1 1 1 1"/>
  </material>

  <xacro:include filename="$(find my_robot_manipulator)/urdf/spherical.urdf.xacro"/>
  <create/>

  <link name="base_link">
    <visual>
      <origin rpy="0 0 0" xyz="0 0 0"/>
      <geometry>
        <sphere radius="0.1"/>
      </geometry>
      <material name="white"/>
    </visual>
  </link>


  <link name="human/shoulder_center">
    <visual>
      <origin rpy="0 0 0" xyz="0 0 0.050635057485"/>
      <geometry>
        <cylinder length="0.10127011497" radius="0.181172520845"/>
      </geometry>
    </visual>
  </link>

  <joint name="shoulder_center" type="fixed">
    <origin rpy="0 0 0" xyz="0 0 0"/>
    <parent link="base_link"/>
    <child link="human/shoulder_center"/>
  </joint>

  <link name="human/left_arm_mount"/>
  <link name="human/left_shoulder_0"/>
  <link name="human/left_shoulder_1"/>
  <link name="human/left_shoulder">
    <visual>
      <origin rpy="0 1.57079632679 0" xyz="0.147075804738 0 0"/>
      <geometry>
        <cylinder length="0.294151609476" radius="0.05"/>
      </geometry>
    </visual>
  </link>
  <link name="human/left_elbow">
    <visual>
      <origin rpy="0 1.57079632679 0" xyz="0.137074736994 0 0"/>
      <geometry>
        <cylinder length="0.274149473988" radius="0.025"/>
      </geometry>
    </visual>
  </link>
  <link name="human/left_wrist_0"/>
  <link name="human/left_wrist_1"/>
  <link name="human/left_wrist">
    <visual>
      <origin rpy="0 0 0" xyz="0.05 0 0"/>
      <geometry>
        <box size="0.1 0.05 .005"/>
      </geometry>
    </visual>
  </link>
  <link name="human/left_hand"/>
  <!-- Joints -->
  <joint name="left_arm_mount" type="fixed">
    <origin rpy="0 0 1.57079632679" xyz="0 0.181172520845 -0.00609526854636"/>
    <parent link="human/shoulder_center"/>
    <child link="human/left_arm_mount"/>
  </joint>
  <!-- SHOULDER : spherical -->
  <joint name="left_shoulder_0" type="revolute">
    <origin rpy="0 0 0" xyz="0 0 0"/>
    <axis xyz="0 1 0"/>
    <parent link="human/left_arm_mount"/>
    <child link="human/left_shoulder_0"/>
    <limit effort="1" lower="-1.57079632679" upper="1.57079632679" velocity="1"/>
  </joint>
  <joint name="left_shoulder_1" type="revolute">
    <origin rpy="0 0 0" xyz="0 0 0"/>
    <axis xyz="0 0 1"/>
    <parent link="human/left_shoulder_0"/>
    <child link="human/left_shoulder_1"/>
    <limit effort="1" lower="-2.35619449019" upper="1.57079632679" velocity="1"/>
  </joint>
  <joint name="left_shoulder_2" type="revolute">
    <origin rpy="0 0 0" xyz="0 0 0"/>
    <axis xyz="1 0 0"/>
    <parent link="human/left_shoulder_1"/>
    <child link="human/left_shoulder"/>
    <limit effort="1" lower="-1.57079632679" upper="1.57079632679" velocity="1"/>
  </joint>
  <!-- END SHOULDER -->
  <joint name="left_elbow_0" type="revolute">
    <origin rpy="0 0 0" xyz="0.294151609476 0 0"/>
    <axis xyz="0 0 1"/>
    <parent link="human/left_shoulder"/>
    <child link="human/left_elbow"/>
    <limit effort="1" lower="-3.14159265359" upper="0.0" velocity="1"/>
  </joint>
  <joint name="left_wrist_0" type="revolute">
    <origin rpy="0 0 0" xyz="0.274149473988 0 0"/>
    <axis xyz="0 1 0"/>
    <parent link="human/left_elbow"/>
    <child link="human/left_wrist_0"/>
    <limit effort="1" lower="-0.78539816339" upper="0.78539816339" velocity="1"/>
  </joint>
  <joint name="left_wrist_1" type="revolute">
    <origin rpy="0 0 0" xyz="0 0 0"/>
    <axis xyz="0 0 1"/>
    <parent link="human/left_wrist_0"/>
    <child link="human/left_wrist_1"/>
    <limit effort="1" lower="-1.57079632679" upper="1.57079632679" velocity="1"/>
  </joint>
  <joint name="left_wrist_2" type="revolute">
    <origin rpy="0 0 0" xyz="0 0 0"/>
    <axis xyz="1 0 0"/>
    <parent link="human/left_wrist_1"/>
    <child link="human/left_wrist"/>
    <limit effort="1" lower="-1.57079632679" upper="1.57079632679" velocity="1"/>
  </joint>
  <joint name="left_hand" type="fixed">
    <origin rpy="0 0 0" xyz="0.1 0 0"/>
    <parent link="human/left_wrist"/>
    <child link="human/left_hand"/>
  </joint>
</robot>
