<?xml version="1.0" encoding="UTF-8"?>

<!--URDF consist of two main parts: visual and inertial. In here I have only visual part -->

<robot name="myhuman" xmlns:xacro="http://playerstage.sourceforge.net/gazebo/xmlschema/#interface">

  <!-- Constants for human dimensions -->
  <xacro:property name="PI" value="3.1415926535897931"/>
  <xacro:property name="mass" value="1" /> <!-- arbitrary value for mass -->
  <xacro:property name="width" value="0.1" /> <!-- Square dimensions (widthxwidth) of beams -->
  <xacro:property name="length_upperarm" value=".35" /> <!-- Link 1 -->
  <xacro:property name="length_forearm" value="1" /> <!-- Link 2 -->
  <xacro:property name="length_hand" value="1" /> <!-- Link 3 -->
  <xacro:property name="camera_link" value="0.05" /> <!-- Size of square 'camera' box Attach to head after-->

  <!-- Import all Gazebo-customization elements, including Gazebo colors -->
  <xacro:include filename="$(find ur5_with_hand_moveit_config)/human_description/urdf/human_arm.gazebo" />
  <!-- Import Rviz colors -->
  <xacro:include filename="$(find ur5_with_hand_moveit_config)/human_description/urdf/materials.xacro" />
  <!-- Import Spherical joint macro -->
  <xacro:include filename="$(find ur5_with_hand_moveit_config)/human_description/urdf/spherical.urdf.xacro"/>

  <xacro:include filename="$(find ur5_with_hand_moveit_config)/human_description/urdf/spherical.urdf.xacro"/>

  <create/>

  <link name="world"/>
  <joint name="world_joint" type="fixed">
    <parent link="world"/>
    <child link="base_link"/>
    <origin rpy="0.0 0.0 0.0" xyz="0.0 -1.0 1.0"/>
  </joint>

  <link name="base_link">
    <visual>
      <origin rpy="0 0 0" xyz="0 0 0"/>
      <geometry>
        <sphere radius="0.5"/>
      </geometry>
      <material name="white"/>
    </visual>
  </link>

  <xacro:spherical name="joint_1" parent="base_link" child="link_01">
    <origin rpy="0 0 0" xyz="0 0 0"/>
  </xacro:spherical>

    <link name="link_01">
      <visual>
        <origin rpy="0 0 0" xyz="0 0 1.5"/>
        <geometry>
          <cylinder radius="0.5" length="3.0"/>
        </geometry>
        <material name="blue"/>
      </visual>
    </link>

    <joint name="joint_2_ball" type="fixed">
      <origin rpy="0 0 0" xyz="0 0 3.0"/>
      <parent link="link_01"/>
      <child link="link_02_ball"/>
    </joint>

    <link name="link_02_ball">
      <visual>
        <origin rpy="0 1.57 0" xyz="0 0 0"/>
        <geometry>
          <cylinder radius="0.25" length="0.5"/>
        </geometry>
        <material name="white"/>
      </visual>
    </link>

    <joint name="joint_2" type="revolute">
      <axis xyz="-1 0 0"/> <!-- rotate around z-axis-->
      <limit effort="1000.0" lower="-3.14" upper="3.14" velocity="0.5"/>
      <origin rpy="0 0 0" xyz="0 0 0"/>
      <parent link="link_02_ball"/>
      <child link="link_02"/>
    </joint>

    <link name="link_02">
      <visual>
        <origin rpy="0 0 0" xyz="0 0 1.0"/>
        <geometry>
          <cylinder radius="0.25" length="2.0"/>
        </geometry>
        <material name="blue"/>
      </visual>
    </link>

    <joint name="joint_3_ball" type="fixed">
      <origin rpy="0 0 0" xyz="0 0 2.0"/>  <!-- half of the height of the box 0.5-->
      <parent link="link_02"/>
      <child link="link_03_ball"/>
    </joint>

    <link name="link_03_ball">
      <visual>
        <origin rpy="0 0 0" xyz="0 0 0"/>
        <geometry>
          <sphere radius="0.12"/>
        </geometry>
        <material name="white"/>
      </visual>
    </link>

    <xacro:spherical name="joint_3" parent="link_03_ball" child="link_03">
      <origin rpy="0 0 0" xyz="0 0 0"/>
    </xacro:spherical>

    <link name="link_03">
      <visual>
        <origin rpy="0 0 0" xyz="0 0 0.5"/>
        <geometry>
          <cylinder radius="0.13" length="1"/>
        </geometry>
        <material name="blue"/>
      </visual>
    </link>

    <joint name="link_03__gripper_a" type="prismatic">
      <axis xyz="1 0 0"/> <!-- move around z-axis-->
      <limit effort="1000.0" lower="0" upper="1.0" velocity="0.5"/>
      <origin rpy="0 0 0" xyz="0 0 1.0"/>  <!-- half of the height of the box 0.5-->
      <parent link="link_03"/>
      <child link="gripper_a"/>
    </joint>

    <joint name="link_03__gripper_b" type="prismatic">
      <axis xyz="-1 0 0"/> <!-- move around z-axis-->
      <limit effort="1000.0" lower="0" upper="1.0" velocity="0.5"/>
      <origin rpy="0 0 0" xyz="0 0 1.0"/>  <!-- half of the height of the box 0.5-->
      <parent link="link_03"/>
      <child link="gripper_b"/>
    </joint>

    <link name="gripper_a">
      <visual>
        <origin rpy="0 0 0" xyz="0.1 0 0.3"/>
        <geometry>
          <box size="0.2 0.2 0.6"/>
        </geometry>
        <material name="white"/>
      </visual>
    </link>

    <link name="gripper_b">
      <visual>
        <origin rpy="0 0 0" xyz="-0.1 0 0.3"/>
        <geometry>
          <box size="0.2 0.2 0.6"/>
        </geometry>
        <material name="white"/>
      </visual>
    </link>

</robot>
